<?xml version='1.0'?>
<sdf version="1.5">
<model name="octanis1_rover_model">
  <static>false</static>
  <pose>0 0 0.075 0 0 0</pose>
    <link name="rover_body">
      <inertial>
        <mass>1.0</mass>
        <inertia> <!-- interias are tricky to compute -->
          <!-- http://answers.gazebosim.org/question/4372/the-inertia-matrix-explained/ -->
          <ixx>0.083</ixx>       <!-- for a box: ixx = 0.083 * mass * (y*y + z*z) -->
          <ixy>0.0</ixy>         <!-- for a box: ixy = 0 -->
          <ixz>0.0</ixz>         <!-- for a box: ixz = 0 -->
          <iyy>0.083</iyy>       <!-- for a box: iyy = 0.083 * mass * (x*x + z*z) -->
          <iyz>0.0</iyz>         <!-- for a box: iyz = 0 -->
          <izz>0.083</izz>       <!-- for a box: izz = 0.083 * mass * (x*x + y*y) -->
        </inertia>
      </inertial>
      <collision name="collision">
        <geometry>
          <box>
            <size>0.3 0.3 0.15</size>
          </box>
        </geometry>
      </collision>
      <visual name="visual">
        <geometry>
          <box>
            <size>0.3 0.3 0.15</size>
          </box>
        </geometry>
      </visual>
    </link>

    <link name="left_strut_out">
      <pose>0.16 0.172 0 0 1.5707 0</pose>
      <inertial>
        <mass>0.1</mass>
        <inertia> <!-- interias are tricky to compute -->
          <!-- http://answers.gazebosim.org/question/4372/the-inertia-matrix-explained/ -->
          <ixx>0.083</ixx>       <!-- for a box: ixx = 0.083 * mass * (y*y + z*z) -->
          <ixy>0.0</ixy>         <!-- for a box: ixy = 0 -->
          <ixz>0.0</ixz>         <!-- for a box: ixz = 0 -->
          <iyy>0.083</iyy>       <!-- for a box: iyy = 0.083 * mass * (x*x + z*z) -->
          <iyz>0.0</iyz>         <!-- for a box: iyz = 0 -->
          <izz>0.083</izz>       <!-- for a box: izz = 0.083 * mass * (x*x + y*y) -->
        </inertia>
      </inertial>
      <collision name="collision">
        <geometry>
          <mesh>
            <uri>model://octanis1_rover_model/meshes/Strut_Rev_Umea_METERS.dae</uri>
          </mesh>
        </geometry>
      </collision>
      <visual name='visual'>
        <geometry>
          <mesh>
            <uri>model://octanis1_rover_model/meshes/Strut_Rev_Umea_METERS.dae</uri>
          </mesh>
        </geometry>
      </visual>
    </link>

    <link name="left_strut_in">
      <pose>0.1752 -0.172 0 3.1414 -1.5707 0</pose>
      <inertial>
        <mass>0.1</mass>
        <inertia> <!-- interias are tricky to compute -->
          <!-- http://answers.gazebosim.org/question/4372/the-inertia-matrix-explained/ -->
          <ixx>0.083</ixx>       <!-- for a box: ixx = 0.083 * mass * (y*y + z*z) -->
          <ixy>0.0</ixy>         <!-- for a box: ixy = 0 -->
          <ixz>0.0</ixz>         <!-- for a box: ixz = 0 -->
          <iyy>0.083</iyy>       <!-- for a box: iyy = 0.083 * mass * (x*x + z*z) -->
          <iyz>0.0</iyz>         <!-- for a box: iyz = 0 -->
          <izz>0.083</izz>       <!-- for a box: izz = 0.083 * mass * (x*x + y*y) -->
        </inertia>
      </inertial>
      <collision name="collision">
        <geometry>
          <mesh>
            <uri>model://octanis1_rover_model/meshes/Strut_INNER_Rev_Umea_METERS.dae</uri>
          </mesh>
        </geometry>
      </collision>
      <visual name='visual'>
        <geometry>
          <mesh>
            <uri>model://octanis1_rover_model/meshes/Strut_INNER_Rev_Umea_METERS.dae</uri>
          </mesh>
        </geometry>
      </visual>
    </link>

    <joint type="revolute" name="left_strut_out_hinge">
        <pose>0.15 0 0 0 0 0</pose>
        <parent>left_strut_out</parent>
        <child>rover_body</child>
        <axis>
          <xyz>1 0 0</xyz>
        </axis>
    </joint>

    <joint type="revolute" name="left_strut_in_hinge">
        <pose>0.15 0 0 0 0 0</pose>
        <parent>left_strut_in</parent>
        <child>rover_body</child>
        <axis>
          <xyz>1 0 0</xyz>
        </axis>
    </joint>


    <link name="left_wheel_in">
      <pose>0.242 -0.172 0 0 -1.5707 0</pose>
      <inertial>
        <mass>0.1</mass>
        <inertia> <!-- interias are tricky to compute -->
          <!-- http://answers.gazebosim.org/question/4372/the-inertia-matrix-explained/ -->
          <ixx>0.083</ixx>       <!-- for a box: ixx = 0.083 * mass * (y*y + z*z) -->
          <ixy>0.0</ixy>         <!-- for a box: ixy = 0 -->
          <ixz>0.0</ixz>         <!-- for a box: ixz = 0 -->
          <iyy>0.083</iyy>       <!-- for a box: iyy = 0.083 * mass * (x*x + z*z) -->
          <iyz>0.0</iyz>         <!-- for a box: iyz = 0 -->
          <izz>0.083</izz>       <!-- for a box: izz = 0.083 * mass * (x*x + y*y) -->
        </inertia>
      </inertial>
      <collision name="collision">
        <geometry>
          <mesh>
            <uri>model://octanis1_rover_model/meshes/Wheel_Rev_Umea_METERS.dae</uri>
          </mesh>
        </geometry>
        <surface>
          <friction>
            <ode>
              <mu>100000.0</mu>
              <mu2>100000.0</mu2>
              <slip1>0.0</slip1>
              <slip2>0.0</slip2>
            </ode>
          </friction>
        </surface>
      </collision>
      <visual name='visual'>
        <geometry>
          <mesh>
            <uri>model://octanis1_rover_model/meshes/Wheel_Rev_Umea_METERS.dae</uri>
          </mesh>
        </geometry>
      </visual>
    </link>

    <link name="left_wheel_out">
      <pose>0.242 0.172 0 0 -1.5707 0</pose>
      <inertial>
        <mass>0.1</mass>
        <inertia> <!-- interias are tricky to compute -->
          <!-- http://answers.gazebosim.org/question/4372/the-inertia-matrix-explained/ -->
          <ixx>0.083</ixx>       <!-- for a box: ixx = 0.083 * mass * (y*y + z*z) -->
          <ixy>0.0</ixy>         <!-- for a box: ixy = 0 -->
          <ixz>0.0</ixz>         <!-- for a box: ixz = 0 -->
          <iyy>0.083</iyy>       <!-- for a box: iyy = 0.083 * mass * (x*x + z*z) -->
          <iyz>0.0</iyz>         <!-- for a box: iyz = 0 -->
          <izz>0.083</izz>       <!-- for a box: izz = 0.083 * mass * (x*x + y*y) -->
        </inertia>
      </inertial>
      <collision name="collision">
        <geometry>
          <mesh>
            <uri>model://octanis1_rover_model/meshes/Wheel_Rev_Umea_METERS.dae</uri>
          </mesh>
        </geometry>
        <surface>
          <friction>
            <ode>
              <mu>100000.0</mu>
              <mu2>100000.0</mu2>
              <slip1>0.0</slip1>
              <slip2>0.0</slip2>
            </ode>
          </friction>
        </surface>
      </collision>
      <visual name='visual'>
        <geometry>
          <mesh>
            <uri>model://octanis1_rover_model/meshes/Wheel_Rev_Umea_METERS.dae</uri>
          </mesh>
        </geometry>
      </visual>
    </link>

    <joint type="revolute" name="left_wheel_in_hinge">
        <pose>0 0 0.01 0 0 0</pose>
        <parent>left_wheel_in</parent>
        <child>left_strut_in</child>
        <axis>
          <xyz>0 0 1</xyz>
        </axis>
    </joint>


    <joint type="revolute" name="left_wheel_out_hinge">
        <pose>0 0 0.01 0 0 0</pose>
        <parent>left_wheel_out</parent>
        <child>left_strut_out</child>
        <axis>
          <xyz>0 0 1</xyz>
        </axis>
    </joint>

    <!-- right side -->

    <link name="right_strut_out">
      <pose>-0.16 0.172 0 0 -1.5707 0</pose>
      <inertial>
        <mass>0.1</mass>
        <inertia> <!-- interias are tricky to compute -->
          <!-- http://answers.gazebosim.org/question/4372/the-inertia-matrix-explained/ -->
          <ixx>0.083</ixx>       <!-- for a box: ixx = 0.083 * mass * (y*y + z*z) -->
          <ixy>0.0</ixy>         <!-- for a box: ixy = 0 -->
          <ixz>0.0</ixz>         <!-- for a box: ixz = 0 -->
          <iyy>0.083</iyy>       <!-- for a box: iyy = 0.083 * mass * (x*x + z*z) -->
          <iyz>0.0</iyz>         <!-- for a box: iyz = 0 -->
          <izz>0.083</izz>       <!-- for a box: izz = 0.083 * mass * (x*x + y*y) -->
        </inertia>
      </inertial>
      <collision name="collision">
        <geometry>
          <mesh>
            <uri>model://octanis1_rover_model/meshes/Strut_Rev_Umea_METERS.dae</uri>
          </mesh>
        </geometry>
      </collision>
      <visual name='visual'>
        <geometry>
          <mesh>
            <uri>model://octanis1_rover_model/meshes/Strut_Rev_Umea_METERS.dae</uri>
          </mesh>
        </geometry>
      </visual>
    </link>

    <link name="right_strut_in">
      <pose>-0.1752 -0.172 0 3.1414 1.5707 0</pose>
      <inertial>
        <mass>0.1</mass>
        <inertia> <!-- interias are tricky to compute -->
          <!-- http://answers.gazebosim.org/question/4372/the-inertia-matrix-explained/ -->
          <ixx>0.083</ixx>       <!-- for a box: ixx = 0.083 * mass * (y*y + z*z) -->
          <ixy>0.0</ixy>         <!-- for a box: ixy = 0 -->
          <ixz>0.0</ixz>         <!-- for a box: ixz = 0 -->
          <iyy>0.083</iyy>       <!-- for a box: iyy = 0.083 * mass * (x*x + z*z) -->
          <iyz>0.0</iyz>         <!-- for a box: iyz = 0 -->
          <izz>0.083</izz>       <!-- for a box: izz = 0.083 * mass * (x*x + y*y) -->
        </inertia>
      </inertial>
      <collision name="collision">
        <geometry>
          <mesh>
            <uri>model://octanis1_rover_model/meshes/Strut_INNER_Rev_Umea_METERS.dae</uri>
          </mesh>
        </geometry>
      </collision>
      <visual name='visual'>
        <geometry>
          <mesh>
            <uri>model://octanis1_rover_model/meshes/Strut_INNER_Rev_Umea_METERS.dae</uri>
          </mesh>
        </geometry>
      </visual>
    </link>

    <joint type="revolute" name="right_strut_out_hinge">
        <pose>-0.15 0 0 0 0 0</pose>
        <parent>right_strut_out</parent>
        <child>rover_body</child>
        <axis>
          <xyz>-1 0 0</xyz>
        </axis>
    </joint>

    <joint type="revolute" name="right_strut_in_hinge">
        <pose>-0.15 0 0 0 0 0</pose>
        <parent>right_strut_in</parent>
        <child>rover_body</child>
        <axis>
          <xyz>1 0 0</xyz>
        </axis>
    </joint>


    <link name="right_wheel_in">
      <pose>-0.222 -0.172 0 0 1.5707 0</pose>
      <inertial>
        <mass>0.1</mass>
        <inertia> <!-- interias are tricky to compute -->
          <!-- http://answers.gazebosim.org/question/4372/the-inertia-matrix-explained/ -->
          <ixx>0.083</ixx>       <!-- for a box: ixx = 0.083 * mass * (y*y + z*z) -->
          <ixy>0.0</ixy>         <!-- for a box: ixy = 0 -->
          <ixz>0.0</ixz>         <!-- for a box: ixz = 0 -->
          <iyy>0.083</iyy>       <!-- for a box: iyy = 0.083 * mass * (x*x + z*z) -->
          <iyz>0.0</iyz>         <!-- for a box: iyz = 0 -->
          <izz>0.083</izz>       <!-- for a box: izz = 0.083 * mass * (x*x + y*y) -->
        </inertia>
      </inertial>
      <collision name="collision">
        <geometry>
          <mesh>
            <uri>model://octanis1_rover_model/meshes/Wheel_Rev_Umea_METERS.dae</uri>
          </mesh>
        </geometry>
        <surface>
          <friction>
            <ode>
              <mu>100000.0</mu>
              <mu2>100000.0</mu2>
              <slip1>0.0</slip1>
              <slip2>0.0</slip2>
            </ode>
          </friction>
        </surface>
      </collision>
      <visual name='visual'>
        <geometry>
          <mesh>
            <uri>model://octanis1_rover_model/meshes/Wheel_Rev_Umea_METERS.dae</uri>
          </mesh>
        </geometry>
      </visual>
    </link>

    <link name="right_wheel_out">
      <pose>-0.222 0.172 0 0 1.5707 0</pose>
      <inertial>
        <mass>0.1</mass>
        <inertia> <!-- interias are tricky to compute -->
          <!-- http://answers.gazebosim.org/question/4372/the-inertia-matrix-explained/ -->
          <ixx>0.083</ixx>       <!-- for a box: ixx = 0.083 * mass * (y*y + z*z) -->
          <ixy>0.0</ixy>         <!-- for a box: ixy = 0 -->
          <ixz>0.0</ixz>         <!-- for a box: ixz = 0 -->
          <iyy>0.083</iyy>       <!-- for a box: iyy = 0.083 * mass * (x*x + z*z) -->
          <iyz>0.0</iyz>         <!-- for a box: iyz = 0 -->
          <izz>0.083</izz>       <!-- for a box: izz = 0.083 * mass * (x*x + y*y) -->
        </inertia>
      </inertial>
      <collision name="collision">
        <geometry>
          <mesh>
            <uri>model://octanis1_rover_model/meshes/Wheel_Rev_Umea_METERS.dae</uri>
          </mesh>
        </geometry>
        <surface>
          <friction>
            <ode>
              <mu>100000.0</mu>
              <mu2>100000.0</mu2>
              <slip1>0.0</slip1>
              <slip2>0.0</slip2>
            </ode>
          </friction>
        </surface>
      </collision>
      <visual name='visual'>
        <geometry>
          <mesh>
            <uri>model://octanis1_rover_model/meshes/Wheel_Rev_Umea_METERS.dae</uri>
          </mesh>
        </geometry>
      </visual>
    </link>

    <joint type="revolute" name="right_wheel_in_hinge">
        <pose>0 0 0.01 0 0 0</pose>
        <parent>right_wheel_in</parent>
        <child>right_strut_in</child>
        <axis>
          <xyz>0 0 1</xyz>
        </axis>
    </joint>


    <joint type="revolute" name="right_wheel_out_hinge">
        <pose>0 0 0.01 0 0 0</pose>
        <parent>right_wheel_out</parent>
        <child>right_strut_out</child>
        <axis>
          <xyz>0 0 1</xyz>
        </axis>
    </joint>



  </model>
</sdf>